INFO     root:test_calc_app.py:31 succes db connection